Workbook

Sheet Project_Brief
A1: CUSTOMER CHURN & RETENTION ANALYTICS
A2: Company (fictional) | B2: ConnectPlus Telecom
A3: Your Role | B3: Business Analytics / Data Analyst
A4: Business Problem | B4: Customer churn is reducing recurring revenue. Management wants to identify churn drivers, high-risk customer segments, and actionable retention opportunities.
A5: Primary Objective | B5: Analyze customer behavior, quantify churn and revenue exposure, identify key churn drivers, and recommend data-driven retention strategies.
A6: Dataset Size | B6: 10,050 raw rows (10,000 base customers + 50 intentional duplicate rows)
A7: Important | B7: This RAW dataset intentionally contains a small number of missing values, duplicate rows, casing inconsistencies, and extra spaces so you can demonstrate data cleaning.
A8: Suggested Workflow | B8: Excel Cleaning → SQL Analysis → Python EDA → Segmentation → Power BI → Optional ML → Business Recommendations
A9: Target KPI 1 | B9: Total Customers
A10: Target KPI 2 | B10: Churned Customers
A11: Target KPI 3 | B11: Churn Rate
A12: Target KPI 4 | B12: Monthly Revenue
A13: Target KPI 5 | B13: Revenue at Risk

Sheet Data_Dictionary
A1: Column | B1: Meaning | C1: Data Type | D1: Example / Allowed Values | E1: Why It Matters
A2: Customer_ID | B2: Unique customer identifier | C2: Text | D2: CP00001 | E2: Used to uniquely identify and deduplicate customers
A3: Age | B3: Customer age in years | C3: Integer | D3: 18–75 | E3: Customer profile / demographic analysis
A4: Gender | B4: Customer gender | C4: Category | D4: Male, Female | E4: Customer profile analysis
A5: City | B5: Customer city | C5: Category | D5: Pune, Mumbai, Bengaluru... | E5: Geographic segmentation
A6: Tenure_Months | B6: Months since customer joined | C6: Integer | D6: 1–72 | E6: Measures customer relationship length
A7: Contract_Type | B7: Subscription commitment | C7: Category | D7: Monthly, Annual, 2-Year | E7: Major potential churn driver
A8: Plan_Type | B8: Current subscription plan | C8: Category | D8: Basic, Standard, Premium | E8: Product / plan analysis
A9: Monthly_Charges | B9: Current monthly billing amount | C9: Decimal | D9: ₹299+ | E9: Revenue and price sensitivity analysis
A10: Total_Charges | B10: Approx. cumulative charges paid | C10: Decimal | D10: Derived from tenure, charges and discount | E10: Customer value and revenue analysis
A11: Payment_Method | B11: How the customer pays | C11: Category | D11: UPI, Card, Bank Transfer, Auto Debit | E11: Payment behavior analysis
A12: Internet_Service | B12: Whether internet service is active | C12: Category | D12: Yes, No | E12: Service usage analysis
... A18: Churn | B18: Whether customer left the company | C18: Category / Target | D18: Yes, No | E18: Primary outcome variable

Sheet Raw_Customer_Data

Sheet Cleaned_Customer_Data 1
A1: Customer_ID | B1: Age | C1: Gender | D1: City | E1: Tenure_Months | F1: Contract_Type | G1: Plan_Type | H1: Monthly_Charges | I1: Total_Charges | J1: Payment_Method | K1: Internet_Service | L1: Support_Calls | M1: Complaints | N1: Satisfaction_Score | O1: Discount_Percent | P1: Referral | Q1: Churn | R1: Risk_Score | S1: Risk_Level
A2: CP00001 | B2: 34 | C2: Female | D2: Mumbai | E2: 40 | F2: Monthly | G2: Basic | H2: 543 | I2: 21852.95 | J2: UPI | K2: Yes | L2: 0 | M2: 0 | N2: 5 | O2: 0 | P2: Yes | Q2: No | R2: =IF(F2="Monthly",2,0) +IF(E2<=6,2,0) +IF(N2<=2,2,0) +IF(L2>=4,2,0) +IF(M2>=2,1,0) +IF(H2>=_xlfn.PERCENTILE.INC($H$2:$H$10001,0.75),1,0) -> 2 | S2: =IF(R2>=7,"High",IF(R2>=4,"Medium","Low")) -> Low
A3: CP00002 | B3: 32 | C3: Female | D3: Mumbai | E3: 8 | F3: Annual | G3: Standard | H3: 778 | I3: 5704.82 | J3: UPI | K3: Yes | L3: 2 | M3: 0 | N3: 5 | O3: 10 | P3: No | Q3: No | R3: =IF(F3="Monthly",2,0) +IF(E3<=6,2,0) +IF(N3<=2,2,0) +IF(L3>=4,2,0) +IF(M3>=2,1,0) +IF(H3>=_xlfn.PERCENTILE.INC($H$2:$H$10001,0.75),1,0) -> 0 | S3: =IF(R3>=7,"High",IF(R3>=4,"Medium","Low")) -> Low
A4: CP00003 | B4: 42 | C4: Male | D4: Nagpur | E4: 54 | F4: Annual | G4: Basic | H4: 536 | I4: 28735.82 | J4: UPI | K4: Yes | L4: 1 | M4: 0 | N4: 5 | O4: 0 | P4: No | Q4: No | R4: =IF(F4="Monthly",2,0) +IF(E4<=6,2,0) +IF(N4<=2,2,0) +IF(L4>=4,2,0) +IF(M4>=2,1,0) +IF(H4>=_xlfn.PERCENTILE.INC($H$2:$H$10001,0.75),1,0) -> 0 | S4: =IF(R4>=7,"High",IF(R4>=4,"Medium","Low")) -> Low
A5: CP00004 | B5: 18 | C5: Female | D5: Mumbai | E5: 42 | F5: Annual | G5: Basic | H5: 594 | I5: 25224.35 | J5: Bank Transfer | K5: Yes | L5: 0 | M5: 0 | N5: 4 | O5: 0 | P5: No | Q5: No | R5: =IF(F5="Monthly",2,0) +IF(E5<=6,2,0) +IF(N5<=2,2,0) +IF(L5>=4,2,0) +IF(M5>=2,1,0) +IF(H5>=_xlfn.PERCENTILE.INC($H$2:$H$10001,0.75),1,0) -> 0 | S5: =IF(R5>=7,"High",IF(R5>=4,"Medium","Low")) -> Low
A6: CP00005 | B6: 58 | C6: Male | D6: Mumbai | E6: 19 | F6: Monthly | G6: Basic | H6: 489 | I6: 9159.93 | J6: Credit Card | K6: No | L6: 1 | M6: 0 | N6: 4 | O6: 0 | P6: No | Q6: Yes | R6: =IF(F6="Monthly",2,0) +IF(E6<=6,2,0) +IF(N6<=2,2,0) +IF(L6>=4,2,0) +IF(M6>=2,1,0) +IF(H6>=_xlfn.PERCENTILE.INC($H$2:$H$10001,0.75),1,0) -> 2 | S6: =IF(R6>=7,"High",IF(R6>=4,"Medium","Low")) -> Low
A7: CP00006 | B7: 50 | C7: Female | D7: Chennai | E7: 27 | F7: Annual | G7: Standard | H7: 769 | I7: 20619.45 | J7: Bank Transfer | K7: Yes | L7: 3 | M7: 1 | N7: 4 | O7: 0 | P7: No | Q7: No | R7: =IF(F7="Monthly",2,0) +IF(E7<=6,2,0) +IF(N7<=2,2,0) +IF(L7>=4,2,0) +IF(M7>=2,1,0) +IF(H7>=_xlfn.PERCENTILE.INC($H$2:$H$10001,0.75),1,0) -> 0 | S7: =IF(R7>=7,"High",IF(R7>=4,"Medium","Low")) -> Low
A8: CP00007 | B8: 27 | C8: Male | D8: Chennai | E8: 61 | F8: 2-Year | G8: Basic | H8: 476 | I8: 28623.79 | J8: Credit Card | K8: Yes | L8: 1 | M8: 0 | N8: 5 | O8: 0 | P8: No | Q8: No | R8: =IF(F8="Monthly",2,0) +IF(E8<=6,2,0) +IF(N8<=2,2,0) +IF(L8>=4,2,0) +IF(M8>=2,1,0) +IF(H8>=_xlfn.PERCENTILE.INC($H$2:$H$10001,0.75),1,0) -> 0 | S8: =IF(R8>=7,"High",IF(R8>=4,"Medium","Low")) -> Low
A9: CP00008 | B9: 46 | C9: Female | D9: Ahmedabad | E9: 23 | F9: Monthly | G9: Standard | H9: 680 | I9: 15474.99 | J9: Bank Transfer | K9: Yes | L9: 1 | M9: 0 | N9: 5 | O9: 0 | P9: Yes | Q9: Yes | R9: =IF(F9="Monthly",2,0) +IF(E9<=6,2,0) +IF(N9<=2,2,0) +IF(L9>=4,2,0) +IF(M9>=2,1,0) +IF(H9>=_xlfn.PERCENTILE.INC($H$2:$H$10001,0.75),1,0) -> 2 | S9: =IF(R9>=7,"High",IF(R9>=4,"Medium","Low")) -> Low
A10: CP00009 | B10: 56 | C10: Female | D10: Mumbai | E10: 20 | F10: Annual | G10: Basic | H10: 450 | I10: 8325.68 | J10: UPI | K10: No | L10: 1 | M10: 0 | N10: 4 | O10: 10 | P10: No | Q10: No | R10: =IF(F10="Monthly",2,0) +IF(E10<=6,2,0) +IF(N10<=2,2,0) +IF(L10>=4,2,0) +IF(M10>=2,1,0) +IF(H10>=_xlfn.PERCENTILE.INC($H$2:$H$10001,0.75),1,0) -> 0 | S10: =IF(R10>=7,"High",IF(R10>=4,"Medium","Low")) -> Low
A11: CP00010 | B11: 36 | C11: Female | D11: Bengaluru | E11: 52 | F11: Monthly | G11: Standard | H11: 771 | I11: 40304.74 | J11: UPI | K11: Yes | L11: 0 | M11: 0 | N11: 4 | O11: 0 | P11: No | Q11: Yes | R11: =IF(F11="Monthly",2,0) +IF(E11<=6,2,0) +IF(N11<=2,2,0) +IF(L11>=4,2,0) +IF(M11>=2,1,0) +IF(H11>=_xlfn.PERCENTILE.INC($H$2:$H$10001,0.75),1,0) -> 2 | S11: =IF(R11>=7,"High",IF(R11>=4,"Medium","Low")) -> Low
A12: CP00011 | B12: 34 | C12: Male | D12: Jaipur | E12: 17 | F12: Monthly | G12: Premium | H12: 1063 | I12: 18404.41 | J12: UPI | K12: Yes | L12: 3 | M12: 1 | N12: 3 | O12: 0 | P12: No | Q12: Yes | R12: =IF(F12="Monthly",2,0) +IF(E12<=6,2,0) +IF(N12<=2,2,0) +IF(L12>=4,2,0) +IF(M12>=2,1,0) +IF(H12>=_xlfn.PERCENTILE.INC($H$2:$H$10001,0.75),1,0) -> 3 | S12: =IF(R12>=7,"High",IF(R12>=4,"Medium","Low")) -> Low
A13: CP00012 | B13: 30 | C13: Male | D13: Delhi | E13: 49 | F13: Monthly | G13: Basic | H13: 418 | I13: 20039.81 | J13: Bank Transfer | K13: Yes | L13: 2 | M13: 1 | N13: 5 | O13: 0 | P13: No | Q13: Yes | R13: =IF(F13="Monthly",2,0) +IF(E13<=6,2,0) +IF(N13<=2,2,0) +IF(L13>=4,2,0) +IF(M13>=2,1,0) +IF(H13>=_xlfn.PERCENTILE.INC($H$2:$H$10001,0.75),1,0) -> 2 | S13: =IF(R13>=7,"High",IF(R13>=4,"Medium","Low")) -> Low
... A306: CP00305 | B306: 34 | C306: Male | D306: Mumbai | E306: 55 | F306: Monthly | G306: Standard | H306: 656 | I306: 35759.42 | J306: Debit Card | K306: Yes | L306: 0 | M306: 0 | N306: 5 | O306: 0 | P306: No | Q306: No | R306: =IF(F306="Monthly",2,0) +IF(E306<=6,2,0) +IF(N306<=2,2,0) +IF(L306>=4,2,0) +IF(M306>=2,1,0) +IF(H306>=_xlfn.PERCENTILE.INC($H$2:$H$10001,0.75),1,0) -> 2 | S306: =IF(R306>=7,"High",IF(R306>=4,"Medium","Low")) -> Low
A307: CP00306 | B307: 39 | C307: Male | D307: Nagpur | E307: 9 | F307: Monthly | G307: Premium | H307: 1004 | I307: 8847.17 | J307: Auto Debit | K307: Yes | L307: 2 | M307: 1 | N307: =MEDIAN(1,5) -> 3 | O307: 0 | P307: Yes | Q307: No | R307: =IF(F307="Monthly",2,0) +IF(E307<=6,2,0) +IF(N307<=2,2,0) +IF(L307>=4,2,0) +IF(M307>=2,1,0) +IF(H307>=_xlfn.PERCENTILE.INC($H$2:$H$10001,0.75),1,0) -> 3 | S307: =IF(R307>=7,"High",IF(R307>=4,"Medium","Low")) -> Low
A308: CP00307 | B308: 33 | C308: Female | D308: Hyderabad | E308: 51 | F308: 2-Year | G308: Standard | H308: 700 | I308: 31564.69 | J308: Credit Card | K308: Yes | L308: 0 | M308: 0 | N308: 5 | O308: 10 | P308: No | Q308: No | R308: =IF(F308="Monthly",2,0) +IF(E308<=6,2,0) +IF(N308<=2,2,0) +IF(L308>=4,2,0) +IF(M308>=2,1,0) +IF(H308>=_xlfn.PERCENTILE.INC($H$2:$H$10001,0.75),1,0) -> 0 | S308: =IF(R308>=7,"High",IF(R308>=4,"Medium","Low")) -> Low
A309: CP00308 | B309: 18 | C309: Male | D309: Bengaluru | E309: 18 | F309: Annual | G309: Standard | H309: 803 | I309: 14684.2 | J309: Debit Card | K309: Yes | L309: 5 | M309: 1 | N309: 4 | O309: 0 | P309: No | Q309: No | R309: =IF(F309="Monthly",2,0) +IF(E309<=6,2,0) +IF(N309<=2,2,0) +IF(L309>=4,2,0) +IF(M309>=2,1,0) +IF(H309>=_xlfn.PERCENTILE.INC($H$2:$H$10001,0.75),1,0) -> 3 | S309: =IF(R309>=7,"High",IF(R309>=4,"Medium","Low")) -> Low
A310: CP00309 | B310: 42 | C310: Female | D310: Nagpur | E310: 52 | F310: Annual | G310: Basic | H310: 427 | I310: 21845.51 | J310: UPI | K310: No | L310: 0 | M310: 0 | N310: 5 | O310: 0 | P310: Yes | Q310: No | R310: =IF(F310="Monthly",2,0) +IF(E310<=6,2,0) +IF(N310<=2,2,0) +IF(L310>=4,2,0) +IF(M310>=2,1,0) +IF(H310>=_xlfn.PERCENTILE.INC($H$2:$H$10001,0.75),1,0) -> 0 | S310: =IF(R310>=7,"High",IF(R310>=4,"Medium","Low")) -> Low
A311: CP00310 | B311: 20 | C311: Male | D311: Bengaluru | E311: 28 | F311: Monthly | G311: Standard | H311: 833 | I311: 22669.38 | J311: Credit Card | K311: Yes | L311: 3 | M311: 0 | N311: 5 | O311: 0 | P311: Yes | Q311: No | R311: =IF(F311="Monthly",2,0) +IF(E311<=6,2,0) +IF(N311<=2,2,0) +IF(L311>=4,2,0) +IF(M311>=2,1,0) +IF(H311>=_xlfn.PERCENTILE.INC($H$2:$H$10001,0.75),1,0) -> 3 | S311: =IF(R311>=7,"High",IF(R311>=4,"Medium","Low")) -> Low
A312: CP00311 | B312: 44 | C312: Female | D312: Mumbai | E312: 16 | F312: Monthly | G312: Standard | H312: 722 | I312: 11376.49 | J312: Debit Card | K312: Yes | L312: 0 | M312: 0 | N312: 5 | O312: 0 | P312: No | Q312: No | R312: =IF(F312="Monthly",2,0) +IF(E312<=6,2,0) +IF(N312<=2,2,0) +IF(L312>=4,2,0) +IF(M312>=2,1,0) +IF(H312>=_xlfn.PERCENTILE.INC($H$2:$H$10001,0.75),1,0) -> 2 | S312: =IF(R312>=7,"High",IF(R312>=4,"Medium","Low")) -> Low
A313: CP00312 | B313: 53 | C313: Female | D313: Chennai | E313: 47 | F313: 2-Year | G313: Standard | H313: 773 | I313: 33439.06 | J313: Bank Transfer | K313: Yes | L313: 0 | M313: 0 | N313: 5 | O313: 10 | P313: Yes | Q313: No | R313: =IF(F313="Monthly",2,0) +IF(E313<=6,2,0) +IF(N313<=2,2,0) +IF(L313>=4,2,0) +IF(M313>=2,1,0) +IF(H313>=_xlfn.PERCENTILE.INC($H$2:$H$10001,0.75),1,0) -> 0 | S313: =IF(R313>=7,"High",IF(R313>=4,"Medium","Low")) -> Low
A314: CP00313 | B314: 18 | C314: Male | D314: Delhi | E314: 15 | F314: Annual | G314: Standard | H314: 786 | I314: 11328.15 | J314: Bank Transfer | K314: Yes | L314: 0 | M314: 0 | N314: 5 | O314: 5 | P314: Yes | Q314: No | R314: =IF(F314="Monthly",2,0) +IF(E314<=6,2,0) +IF(N314<=2,2,0) +IF(L314>=4,2,0) +IF(M314>=2,1,0) +IF(H314>=_xlfn.PERCENTILE.INC($H$2:$H$10001,0.75),1,0) -> 0 | S314: =IF(R314>=7,"High",IF(R314>=4,"Medium","Low")) -> Low
A315: CP00314 | B315: 20 | C315: Male | D315: Chennai | E315: 61 | F315: Annual | G315: Basic | H315: 489 | I315: 29295.54 | J315: Credit Card | K315: Yes | L315: 0 | M315: 0 | N315: 5 | O315: 0 | P315: No | Q315: No | R315: =IF(F315="Monthly",2,0) +IF(E315<=6,2,0) +IF(N315<=2,2,0) +IF(L315>=4,2,0) +IF(M315>=2,1,0) +IF(H315>=_xlfn.PERCENTILE.INC($H$2:$H$10001,0.75),1,0) -> 0 | S315: =IF(R315>=7,"High",IF(R315>=4,"Medium","Low")) -> Low
A316: CP00315 | B316: 35 | C316: Male | D316: Chennai | E316: 26 | F316: Monthly | G316: Basic | H316: 481 | I316: 12543.78 | J316: Bank Transfer | K316: Yes | L316: 2 | M316: 2 | N316: 5 | O316: 0 | P316: Yes | Q316: Yes | R316: =IF(F316="Monthly",2,0) +IF(E316<=6,2,0) +IF(N316<=2,2,0) +IF(L316>=4,2,0) +IF(M316>=2,1,0) +IF(H316>=_xlfn.PERCENTILE.INC($H$2:$H$10001,0.75),1,0) -> 3 | S316: =IF(R316>=7,"High",IF(R316>=4,"Medium","Low")) -> Low
A317: CP00316 | B317: 33 | C317: Male | D317: Jaipur | E317: 19 | F317: Annual | G317: Standard | H317: 684 | I317: 12687.28 | J317: UPI | K317: Yes | L317: 0 | M317: 0 | N317: 5 | O317: 5 | P317: Yes | Q317: Yes | R317: =IF(F317="Monthly",2,0) +IF(E317<=6,2,0) +IF(N317<=2,2,0) +IF(L317>=4,2,0) +IF(M317>=2,1,0) +IF(H317>=_xlfn.PERCENTILE.INC($H$2:$H$10001,0.75),1,0) -> 0 | S317: =IF(R317>=7,"High",IF(R317>=4,"Medium","Low")) -> Low
A318: CP00317 | B318: 18 | C318: Female | D318: Pune | E318: 44 | F318: Monthly | G318: Standard | H318: 794 | I318: 35145.83 | J318: UPI | K318: Yes | L318: 1 | M318: 0 | N318: 4 | O318: 0 | P318: Yes | Q318: No | R318: =IF(F318="Monthly",2,0) +IF(E318<=6,2,0) +IF(N318<=2,2,0) +IF(L318>=4,2,0) +IF(M318>=2,1,0) +IF(H318>=_xlfn.PERCENTILE.INC($H$2:$H$10001,0.75),1,0) -> 3 | S318: =IF(R318>=7,"High",IF(R318>=4,"Medium","Low")) -> Low
A319: CP00318 | B319: 37 | C319: Female | D319: Delhi | E319: 13 | F319: Annual | G319: Standard | H319: 685 | I319: 8251.92 | J319: Auto Debit | K319: Yes | L319: 1 | M319: 0 | N319: 5 | O319: 10 | P319: No | Q319: No | R319: =IF(F319="Monthly",2,0) +IF(E319<=6,2,0) +IF(N319<=2,2,0) +IF(L319>=4,2,0) +IF(M319>=2,1,0) +IF(H319>=_xlfn.PERCENTILE.INC($H$2:$H$10001,0.75),1,0) -> 0 | S319: =IF(R319>=7,"High",IF(R319>=4,"Medium","Low")) -> Low
... A393: CP00392 | B393: 47 | C393: Male | D393: Hyderabad | E393: 35 | F393: 2-Year | G393: Standard | H393: 776 | I393: 26646.88 | J393: Bank Transfer | K393: Yes | L393: 4 | M393: 2 | N393: 4 | O393: 0 | P393: No | Q393: No | R393: =IF(F393="Monthly",2,0) +IF(E393<=6,2,0) +IF(N393<=2,2,0) +IF(L393>=4,2,0) +IF(M393>=2,1,0) +IF(H393>=_xlfn.PERCENTILE.INC($H$2:$H$10001,0.75),1,0) -> 3 | S393: =IF(R393>=7,"High",IF(R393>=4,"Medium","Low")) -> Low
A394: CP00393 | B394: 25 | C394: Male | D394: Mumbai | E394: 17 | F394: Monthly | G394: Basic | H394: 483 | I394: =RawCustomerTable[[#This Row],[Monthly_Charges]]*RawCustomerTable[[#This Row],[Tenure_Months]]*(1-RawCustomerTable[[#This Row],[Discount_Percent]]/100) -> 8211 | J394: Auto Debit | K394: Yes | L394: 0 | M394: 0 | N394: 5 | O394: 0 | P394: No | Q394: No | R394: =IF(F394="Monthly",2,0) +IF(E394<=6,2,0) +IF(N394<=2,2,0) +IF(L394>=4,2,0) +IF(M394>=2,1,0) +IF(H394>=_xlfn.PERCENTILE.INC($H$2:$H$10001,0.75),1,0) -> 2 | S394: =IF(R394>=7,"High",IF(R394>=4,"Medium","Low")) -> Low
A395: CP00394 | B395: 39 | C395: Male | D395: Pune | E395: 26 | F395: Monthly | G395: Standard | H395: 718 | I395: 19067.62 | J395: Auto Debit | K395: Yes | L395: 0 | M395: 0 | N395: 3 | O395: 0 | P395: No | Q395: No | R395: =IF(F395="Monthly",2,0) +IF(E395<=6,2,0) +IF(N395<=2,2,0) +IF(L395>=4,2,0) +IF(M395>=2,1,0) +IF(H395>=_xlfn.PERCENTILE.INC($H$2:$H$10001,0.75),1,0) -> 2 | S395: =IF(R395>=7,"High",IF(R395>=4,"Medium","Low")) -> Low
A396: CP00395 | B396: 53 | C396: Female | D396: Jaipur | E396: 36 | F396: Monthly | G396: Basic | H396: 415 | I396: 15368.09 | J396: Debit Card | K396: Yes | L396: 2 | M396: 1 | N396: 5 | O396: 0 | P396: No | Q396: No | R396: =IF(F396="Monthly",2,0) +IF(E396<=6,2,0) +IF(N396<=2,2,0) +IF(L396>=4,2,0) +IF(M396>=2,1,0) +IF(H396>=_xlfn.PERCENTILE.INC($H$2:$H$10001,0.75),1,0) -> 2 | S396: =IF(R396>=7,"High",IF(R396>=4,"Medium","Low")) -> Low
A397: CP00396 | B397: 41 | C397: Female | D397: Nagpur | E397: 70 | F397: Annual | G397: Basic | H397: 448 | I397: 30932.83 | J397: Bank Transfer | K397: No | L397: 0 | M397: 0 | N397: 5 | O397: 0 | P397: No | Q397: No | R397: =IF(F397="Monthly",2,0) +IF(E397<=6,2,0) +IF(N397<=2,2,0) +IF(L397>=4,2,0) +IF(M397>=2,1,0) +IF(H397>=_xlfn.PERCENTILE.INC($H$2:$H$10001,0.75),1,0) -> 0 | S397: =IF(R397>=7,"High",IF(R397>=4,"Medium","Low")) -> Low
A398: CP00397 | B398: 29 | C398: Female | D398: Chennai | E398: 38 | F398: 2-Year | G398: Premium | H398: 1055 | I398: 36595.8 | J398: Credit Card | K398: Yes | L398: 0 | M398: 0 | N398: 4 | O398: 10 | P398: No | Q398: No | R398: =IF(F398="Monthly",2,0) +IF(E398<=6,2,0) +IF(N398<=2,2,0) +IF(L398>=4,2,0) +IF(M398>=2,1,0) +IF(H398>=_xlfn.PERCENTILE.INC($H$2:$H$10001,0.75),1,0) -> 1 | S398: =IF(R398>=7,"High",IF(R398>=4,"Medium","Low")) -> Low
A399: CP00398 | B399: 33 | C399: Male | D399: Bengaluru | E399: 33 | F399: Monthly | G399: Standard | H399: 677 | I399: 22064.28 | J399: Debit Card | K399: Yes | L399: 1 | M399: 0 | N399: 5 | O399: 0 | P399: No | Q399: No | R399: =IF(F399="Monthly",2,0) +IF(E399<=6,2,0) +IF(N399<=2,2,0) +IF(L399>=4,2,0) +IF(M399>=2,1,0) +IF(H399>=_xlfn.PERCENTILE.INC($H$2:$H$10001,0.75),1,0) -> 2 | S399: =IF(R399>=7,"High",IF(R399>=4,"Medium","Low")) -> Low
A400: CP00399 | B400: 22 | C400: Male | D400: Nagpur | E400: 53 | F400: Monthly | G400: Basic | H400: 487 | I400: 25310.58 | J400: Auto Debit | K400: Yes | L400: 1 | M400: 0 | N400: 5 | O400: 0 | P400: Yes | Q400: No | R400: =IF(F400="Monthly",2,0) +IF(E400<=6,2,0) +IF(N400<=2,2,0) +IF(L400>=4,2,0) +IF(M400>=2,1,0) +IF(H400>=_xlfn.PERCENTILE.INC($H$2:$H$10001,0.75),1,0) -> 2 | S400: =IF(R400>=7,"High",IF(R400>=4,"Medium","Low")) -> Low
A401: CP00400 | B401: 40 | C401: Male | D401: Hyderabad | E401: 31 | F401: Annual | G401: Basic | H401: 534 | I401: 16446.12 | J401: Bank Transfer | K401: Yes | L401: 2 | M401: 0 | N401: 4 | O401: 0 | P401: No | Q401: No | R401: =IF(F401="Monthly",2,0) +IF(E401<=6,2,0) +IF(N401<=2,2,0) +IF(L401>=4,2,0) +IF(M401>=2,1,0) +IF(H401>=_xlfn.PERCENTILE.INC($H$2:$H$10001,0.75),1,0) -> 0 | S401: =IF(R401>=7,"High",IF(R401>=4,"Medium","Low")) -> Low
A402: CP00401 | B402: 30 | C402: Female | D402: Delhi | E402: 28 | F402: 2-Year | G402: Basic | H402: 552 | I402: 13015.53 | J402: Credit Card | K402: Yes | L402: 2 | M402: 0 | N402: 4 | O402: 15 | P402: No | Q402: No | R402: =IF(F402="Monthly",2,0) +IF(E402<=6,2,0) +IF(N402<=2,2,0) +IF(L402>=4,2,0) +IF(M402>=2,1,0) +IF(H402>=_xlfn.PERCENTILE.INC($H$2:$H$10001,0.75),1,0) -> 0 | S402: =IF(R402>=7,"High",IF(R402>=4,"Medium","Low")) -> Low
A403: CP00402 | B403: 26 | C403: Male | D403: Mumbai | E403: 37 | F403: Monthly | G403: Basic | H403: 484 | I403: 18298.43 | J403: UPI | K403: Yes | L403: 0 | M403: 0 | N403: 5 | O403: 0 | P403: No | Q403: No | R403: =IF(F403="Monthly",2,0) +IF(E403<=6,2,0) +IF(N403<=2,2,0) +IF(L403>=4,2,0) +IF(M403>=2,1,0) +IF(H403>=_xlfn.PERCENTILE.INC($H$2:$H$10001,0.75),1,0) -> 2 | S403: =IF(R403>=7,"High",IF(R403>=4,"Medium","Low")) -> Low
A404: CP00403 | B404: 43 | C404: Female | D404: Delhi | E404: 23 | F404: Monthly | G404: Premium | H404: 1101 | I404: 25327.21 | J404: UPI | K404: Yes | L404: 1 | M404: 0 | N404: 5 | O404: 0 | P404: No | Q404: No | R404: =IF(F404="Monthly",2,0) +IF(E404<=6,2,0) +IF(N404<=2,2,0) +IF(L404>=4,2,0) +IF(M404>=2,1,0) +IF(H404>=_xlfn.PERCENTILE.INC($H$2:$H$10001,0.75),1,0) -> 3 | S404: =IF(R404>=7,"High",IF(R404>=4,"Medium","Low")) -> Low
A405: CP00404 | B405: 27 | C405: Female | D405: Nagpur | E405: 66 | F405: Annual | G405: Basic | H405: 526 | I405: 34975.48 | J405: Credit Card | K405: Yes | L405: 0 | M405: 0 | N405: 5 | O405: 0 | P405: No | Q405: No | R405: =IF(F405="Monthly",2,0) +IF(E405<=6,2,0) +IF(N405<=2,2,0) +IF(L405>=4,2,0) +IF(M405>=2,1,0) +IF(H405>=_xlfn.PERCENTILE.INC($H$2:$H$10001,0.75),1,0) -> 0 | S405: =IF(R405>=7,"High",IF(R405>=4,"Medium","Low")) -> Low
...

Sheet Business_Analysis
A1: CONNECTPLUS CUSTOMER CHURN ANALYSIS
A3: KPI | B3: Value | F3: Risk Factor | G3: Criteria
A4: Total Customers | B4: =COUNTA(RawCustomerTable[Customer_ID]) -> 10000 | F4: Contract | G4: Monthly | R4: Finding | S4: Evidence | T4: Business Impact | U4: Recommendation | V4: Priority
A5: Churned Customers | B5: =[1]!COUNT_IF(RawCustomerTable[Churn],"Yes") -> 2192 | F5: Tenure | G5: ≤ 6 months | R5: Monthly customers have high churn | S5: 31.98% churn | T5: Higher customer attrition | U5: Encourage migration to annual/2-year plans | V5: 🔴 High
A6: Churn Rate | B6: =B5/B4 -> 0.2192 | F6: Satisfaction | G6: ≤ 2 | H6: High-Risk Monthly Revenue | I6: Total Monthly Revenue | J6: High-Risk Revenue % of Total | R6: New customers are high risk | S6: 0–6 months = 56% churn | T6: Early customer loss | U6: Strengthen onboarding & first 6-month engagement | V6: 🔴 High
A7: Monthly Revenue | B7: =SUM(RawCustomerTable[Monthly_Charges]) -> 6984432 | F7: Support Calls | G7: ≥ 4 | H7: =SUMIF('Cleaned_Customer_Data 1'!$S$2:$S$10001,"High",'Cleaned_Customer_Data 1'!$H$2:$H$10001) -> 106612 | I7: =SUM('Cleaned_Customer_Data 1'!$H$2:$H$10001) -> 6984432 | J7: =H7/I7 -> 0.015264233 | R7: High-risk segment has very high churn | S7: 88% observed churn | T7: Strong early-warning signal | U7: Prioritize proactive retention | V7: 🔴 High
A8: Revenue Lost from Churn | B8: =SUMIF(RawCustomerTable[Churn],"Yes",RawCustomerTable[Monthly_Charges]) -> 1548024 | F8: Churn | G8: Yes | R8: Support issues may increase churn | S8: Higher support-call groups show higher churn | T8: Service dissatisfaction | U8: Trigger proactive support escalation | V8: 🟡 Medium
A9: Average Customer Tenure | B9: =AVERAGE(RawCustomerTable[Tenure_Months]) -> 33.8973 | R9: Low satisfaction may indicate churn risk | S9: Use your satisfaction analysis | T9: Customer experience risk | U9: Customer recovery program | V9: 🟡 Medium
A10: Average Monthly Charges | B10: =AVERAGE(RawCustomerTable[Monthly_Charges]) -> 698.4432 | R10: Churn varies across plans | S10: Premium = 23.09%, Basic = 21.15% | T10: Potential product/value issue | U10: Investigate plan-level customer experience | V10: 🟡 Medium
A12: A | B12: B | C12: C | D12: D
A13: Contract Type | B13: Total Customers | C13: Churned Customers | D13: Churn Rate | F13: Risk Level | G13: Total Customers | H13: Churned Customers | I13: Churn Rate
A14: Monthly | B14: =COUNTIF(RawCustomerTable[Contract_Type],Business_Analysis!A14) -> 5212 | C14: =COUNTIFS('Cleaned_Customer_Data 1'!F2:F10001,A14,'Cleaned_Customer_Data 1'!Q2:Q10001,"Yes") -> 1667 | D14: =C14/B14 -> 0.31983883 | F14: Low | G14: =COUNTIF('Cleaned_Customer_Data 1'!$S$2:$S$10001,F14) -> 9187 | H14: =COUNTIFS('Cleaned_Customer_Data 1'!$S$2:$S$10001,F14,'Cleaned_Customer_Data 1'!$Q$2:$Q$10001,"Yes") -> 1694 | I14: =H14/G14 -> 0.18439099
A15: Annual | B15: =COUNTIF(RawCustomerTable[Contract_Type],Business_Analysis!A15) -> 3267 | C15: =COUNTIFS('Cleaned_Customer_Data 1'!F3:F10002,A15,'Cleaned_Customer_Data 1'!Q3:Q10002,"Yes") -> 434 | D15: =C15/B15 -> 0.13284359 | F15: Medium | G15: =COUNTIF('Cleaned_Customer_Data 1'!$S$2:$S$10001,F15) -> 655 | H15: =COUNTIFS('Cleaned_Customer_Data 1'!$S$2:$S$10001,F15,'Cleaned_Customer_Data 1'!$Q$2:$Q$10001,"Yes") -> 359 | I15: =H15/G15 -> 0.5480916
A16: 2-Year | B16: =COUNTIF(RawCustomerTable[Contract_Type],Business_Analysis!A16) -> 1521 | C16: =COUNTIFS('Cleaned_Customer_Data 1'!F4:F10003,A16,'Cleaned_Customer_Data 1'!Q4:Q10003,"Yes") -> 91 | D16: =C16/B16 -> 0.05982906 | F16: High | G16: =COUNTIF('Cleaned_Customer_Data 1'!$S$2:$S$10001,F16) -> 158 | H16: =COUNTIFS('Cleaned_Customer_Data 1'!$S$2:$S$10001,F16,'Cleaned_Customer_Data 1'!$Q$2:$Q$10001,"Yes") -> 139 | I16: =H16/G16 -> 0.87974684
F18: CUSTOMER RISK SUMMARY
A19: Plan Type | B19: Total Customers | C19: Churned Customers | D19: Churn Rate | F19: Metric | G19: Value
A20: Basic | B20: =COUNTIF('Cleaned_Customer_Data 1'!G2:G10001,A20) -> 3778 | C20: =COUNTIFS('Cleaned_Customer_Data 1'!G2:G10001,A20,'Cleaned_Customer_Data 1'!Q2:Q10001,"Yes") -> 799 | D20: =C20/B20 -> 0.21148756 | F20: Low Risk Customers | G20: =COUNTIF('Cleaned_Customer_Data 1'!$S$2:$S$10001,"Low") -> 9187
A21: Standard | B21: =COUNTIF('Cleaned_Customer_Data 1'!G3:G10002,A21) -> 4204 | C21: =COUNTIFS('Cleaned_Customer_Data 1'!G3:G10002,A21,'Cleaned_Customer_Data 1'!Q3:Q10002,"Yes") -> 927 | D21: =C21/B21 -> 0.22050428 | F21: Medium Risk Customers | G21: =COUNTIF('Cleaned_Customer_Data 1'!$S$2:$S$10001,"Medium") -> 655
A22: Premium | B22: =COUNTIF('Cleaned_Customer_Data 1'!G4:G10003,A22) -> 2018 | C22: =COUNTIFS('Cleaned_Customer_Data 1'!G4:G10003,A22,'Cleaned_Customer_Data 1'!Q4:Q10003,"Yes") -> 466 | D22: =C22/B22 -> 0.2309217 | F22: High Risk Customers | G22: =COUNTIF('Cleaned_Customer_Data 1'!$S$2:$S$10001,"High") -> 158
F23: High Risk Churn Rate | G23: =I16 -> 0.87974684
F24: High Risk Monthly Revenue | G24: =Business_Analysis!H7 -> 106612
A25: Tenure Group | B25: Total Customers | C25: Churned Customers | D25: Churn Rate | F25: High Risk Revenue % | G25: =Business_Analysis!J7 -> 0.015264233
A26: 0–6 Months | B26: =COUNTIFS('Cleaned_Customer_Data 1'!$E$2:$E$10001,">=1",'Cleaned_Customer_Data 1'!$E$2:$E$10001,"<=6") -> 165 | C26: =COUNTIFS('Cleaned_Customer_Data 1'!$E$2:$E$10001,">=1",'Cleaned_Customer_Data 1'!$E$2:$E$10001,"<=6",'Cleaned_Customer_Data 1'!$Q$2:$Q$10001,"Yes") -> 92 | D26: =C26/B26 -> 0.55757576
A27: 7–12 Months | B27: =COUNTIFS('Cleaned_Customer_Data 1'!$E$2:$E$10001,">=7",'Cleaned_Customer_Data 1'!$E$2:$E$10001,"<=12") -> 539 | C27: =COUNTIFS('Cleaned_Customer_Data 1'!$E$2:$E$10001,">=7",'Cleaned_Customer_Data 1'!$E$2:$E$10001,"<=12",'Cleaned_Customer_Data 1'!$Q$2:$Q$10001,"Yes") -> 167 | D27: =C27/B27 -> 0.30983302 | F27: REVENUE RISK ANALYSIS
A28: 13–24 Months | B28: =COUNTIFS('Cleaned_Customer_Data 1'!$E$2:$E$10001,">=13",'Cleaned_Customer_Data 1'!$E$2:$E$10001,"<=24") -> 2552 | C28: =COUNTIFS('Cleaned_Customer_Data 1'!$E$2:$E$10001,">=13",'Cleaned_Customer_Data 1'!$E$2:$E$10001,"<=24",'Cleaned_Customer_Data 1'!$Q$2:$Q$10001,"Yes") -> 710 | D28: =C28/B28 -> 0.27821317 | F28: Metric | G28: Value
A29: 25–36 Months | B29: =COUNTIFS('Cleaned_Customer_Data 1'!$E$2:$E$10001,">=25",'Cleaned_Customer_Data 1'!$E$2:$E$10001,"<=36") -> 2645 | C29: =COUNTIFS('Cleaned_Customer_Data 1'!$E$2:$E$10001,">=25",'Cleaned_Customer_Data 1'!$E$2:$E$10001,"<=36",'Cleaned_Customer_Data 1'!$Q$2:$Q$10001,"Yes") -> 600 | D29: =C29/B29 -> 0.2268431 | F29: Total Monthly Revenue | G29: =SUM('Cleaned_Customer_Data 1'!$H$2:$H$10001) -> 6984432
A30: 37+ Months | B30: =COUNTIFS('Cleaned_Customer_Data 1'!$E$2:$E$10001,">=37") -> 4099 | C30: =COUNTIFS('Cleaned_Customer_Data 1'!$E$2:$E$10001,">=37",'Cleaned_Customer_Data 1'!$Q$2:$Q$10001,"Yes") -> 623 | D30: =C30/B30 -> 0.15198829 | F30: Churned Customer Revenue | G30: =SUMIF('Cleaned_Customer_Data 1'!$Q$2:$Q$10001,"Yes",'Cleaned_Customer_Data 1'!$H$2:$H$10001) -> 1548024
B31: =SUM(B26:B30) -> 10000 | C31: =SUM(C26:C30) -> 2192 | F31: Churned Revenue % | G31: =G30/G29 -> 0.22163921
F32: High Risk Monthly Revenue | G32: =SUMIF('Cleaned_Customer_Data 1'!$S$2:$S$10001,"High",'Cleaned_Customer_Data 1'!$H$2:$H$10001) -> 106612
F33: High Risk Revenue % | G33: =G32/G29 -> 0.015264233
A34: Satisfaction Score | B34: Total Customers | C34: Churned Customers | D34: Churn Rate | F34: Average Revenue per Customer | G34: =AVERAGE('Cleaned_Customer_Data 1'!$H$2:$H$10001) -> 698.4432
A35: 1 | B35: =COUNTIF('Cleaned_Customer_Data 1'!$N$2:$N$10001,A35) -> 86 | C35: =COUNTIFS('Cleaned_Customer_Data 1'!$N$2:$N$10001,A35,'Cleaned_Customer_Data 1'!$Q$2:$Q$10001,"Yes") -> 63 | D35: =C35/B35 -> 0.73255814 | F35: Average Revenue per Churned Customer | G35: =AVERAGEIF('Cleaned_Customer_Data 1'!$Q$2:$Q$10001,"Yes",'Cleaned_Customer_Data 1'!$H$2:$H$10001) -> 706.21533
A36: 2 | B36: =COUNTIF('Cleaned_Customer_Data 1'!$N$2:$N$10001,A36) -> 206 | C36: =COUNTIFS('Cleaned_Customer_Data 1'!$N$2:$N$10001,A36,'Cleaned_Customer_Data 1'!$Q$2:$Q$10001,"Yes") -> 155 | D36: =C36/B36 -> 0.75242718
A37: 3 | B37: =COUNTIF('Cleaned_Customer_Data 1'!$N$2:$N$10001,A37) -> 627 | C37: =COUNTIFS('Cleaned_Customer_Data 1'!$N$2:$N$10001,A37,'Cleaned_Customer_Data 1'!$Q$2:$Q$10001,"Yes") -> 273 | D37: =C37/B37 -> 0.4354067 | F37: Revenue by Contract Type
A38: 4 | B38: =COUNTIF('Cleaned_Customer_Data 1'!$N$2:$N$10001,A38) -> 2479 | C38: =COUNTIFS('Cleaned_Customer_Data 1'!$N$2:$N$10001,A38,'Cleaned_Customer_Data 1'!$Q$2:$Q$10001,"Yes") -> 485 | D38: =C38/B38 -> 0.1956434 | F38: Contract Type | G38: Total Revenue | H38: Churned Revenue | I38: Churned Revenue %
A39: 5 | B39: =COUNTIF('Cleaned_Customer_Data 1'!$N$2:$N$10001,A39) -> 6602 | C39: =COUNTIFS('Cleaned_Customer_Data 1'!$N$2:$N$10001,A39,'Cleaned_Customer_Data 1'!$Q$2:$Q$10001,"Yes") -> 1216 | D39: =C39/B39 -> 0.18418661 | F39: Monthly | G39: =SUMIF('Cleaned_Customer_Data 1'!$F$2:$F$10001,F39,'Cleaned_Customer_Data 1'!$H$2:$H$10001) -> 3626732 | H39: =SUMIFS('Cleaned_Customer_Data 1'!$H$2:$H$10001,'Cleaned_Customer_Data 1'!$F$2:$F$10001,F39,'Cleaned_Customer_Data 1'!$Q$2:$Q$10001,"Yes") -> 1178320 | I39: =H39/G39 -> 0.32489856
F40: Annual | G40: =SUMIF('Cleaned_Customer_Data 1'!$F$2:$F$10001,F40,'Cleaned_Customer_Data 1'!$H$2:$H$10001) -> 2298657 | H40: =SUMIFS('Cleaned_Customer_Data 1'!$H$2:$H$10001,'Cleaned_Customer_Data 1'!$F$2:$F$10001,F40,'Cleaned_Customer_Data 1'!$Q$2:$Q$10001,"Yes") -> 307175 | I40: =H40/G40 -> 0.13363238
F41: 2-Year | G41: =SUMIF('Cleaned_Customer_Data 1'!$F$2:$F$10001,F41,'Cleaned_Customer_Data 1'!$H$2:$H$10001) -> 1059043 | H41: =SUMIFS('Cleaned_Customer_Data 1'!$H$2:$H$10001,'Cleaned_Customer_Data 1'!$F$2:$F$10001,F41,'Cleaned_Customer_Data 1'!$Q$2:$Q$10001,"Yes") -> 62529 | I41: =H41/G41 -> 0.059042928
A42: Support Call Group | B42: Total Customers | C42: Churned Customers | D42: Churn Rate
A43: 0–1 Calls | B43: =COUNTIFS('Cleaned_Customer_Data 1'!$L$2:$L$10001,">=0",'Cleaned_Customer_Data 1'!$L$2:$L$10001,"<=1") -> 6946 | C43: =COUNTIFS('Cleaned_Customer_Data 1'!$L$2:$L$10001,">=0",'Cleaned_Customer_Data 1'!$L$2:$L$10001,"<=1",'Cleaned_Customer_Data 1'!$Q$2:$Q$10001,"Yes") -> 1261 | D43: =C43/B43 -> 0.18154333
...

Sheet SQL_Business_Insights
A3: No. | B3: Business Question | C3: SQL Technique | D3: Result | E3: Business Insight | F3: Recommendation
A4: 1 | B4: What is the overall customer churn rate? | C4: COUNT, SUM, CASE | D4: 10,000 customers; 2,192 churned; 21.92% churn | E4: Around 22% of customers have churned | F4: Focus retention efforts on high-risk customer segments
A6: No. | B6: Business Question | C6: SQL Technique | D6: Result | E6: Business Insight | F6: Recommendation
A7: 2 | B7: Which contract type has the highest churn? | C7: GROUP BY, CASE, ROUND | D7: Monthly: 31.98%; Annual: 13.28%; 2-Year: 5.98% | E7: Monthly-contract customers show the highest observed churn | F7: Target suitable monthly customers with contract-upgrade/retention offers
A9: No. | B9: Business Question | C9: SQL Technique | D9: Result | E9: Business Insight | F9: Recommendation
A10: 3 | B10: At what stage is churn highest? | C10: CASE, GROUP BY | D10: 0–6 months: 56% | E10: Early-tenure customers show the highest observed churn | F10: Build a First-180-Day onboarding and retention program
A12: No. | B12: Business Question | C12: SQL Technique | D12: Result | E12: Business Insight | F12: Recommendation
A13: 5 | B13: Which payment method has higher churn? | C13: GROUP BY, CASE | D13: Use your SQL output | E13: Identify payment methods with relatively high churn | F13: Investigate billing/payment friction for higher-churn methods
A15: No. | B15: Business Question | C15: SQL Technique | D15: Result | E15: Business Insight | F15: Recommendation
A16: 6 | B16: Which cities have high churn among meaningful customer bases? | C16: GROUP BY, HAVING | D16: Use your SQL output | E16: Identify geographic areas with elevated churn | F16: Investigate local service/customer experience differences
A18: No. | B18: Business Question | C18: SQL Technique | D18: Result | E18: Business Insight | F18: Recommendation
A19: 7 | B19: What monthly charges are associated with churned customers? | C19: SUM, WHERE | D19: 1548024 | E19: Churned customers were associated with ₹15.48 lakh in monthly charges | F19: Prioritize retention strategies around high-value customer segments
A21: No. | B21: Business Question | C21: SQL Technique | D21: Result | E21: Business Insight | F21: Recommendation
A22: 8 | B22: How much monthly revenue is associated with high-value churned customers? | C22: CTE, NTILE | D22: Use your SQL output | E22: Some churned customers belong to the highest revenue quartile | F22: Give high-value churned segments special attention during retention analysis
A24: No. | B24: Business Question | C24: SQL Technique | D24: Result | E24: Business Insight | F24: Recommendation
A25: 9 | B25: How does churn vary by risk level? | C25: CASE, GROUP BY | D25: High: 88%; Medium: 55%; Low: 18% | E25: Higher rule-based risk segments show substantially higher observed churn | F25: Use risk score as a retention prioritization framework
A27: No. | B27: Business Question | C27: SQL Technique | D27: Result | E27: Business Insight | F27: Recommendation
A28: 10 | B28: Which active customers are high risk? | C28: WHERE, ORDER BY, LIMIT | D28: Top 20 customers identified | E28: Some customers have not churned but have high rule-based risk scores | F28: Create a proactive retention queue
A30: No. | B30: Business Question | C30: SQL Technique | D30: Result | E30: Business Insight | F30: Recommendation
A31: 11 | B31: Which active customers are both high-risk and high-value? | C31: CTE, NTILE, WHERE | D31: Top 20 identified | E31: Combines customer risk with financial value | F31: Prioritize these customers for proactive retention
A33: No. | B33: Business Question | C33: SQL Technique | D33: Result | E33: Business Insight | F33: Recommendation
A34: 12 | B34: How much monthly revenue is associated with active high-risk/high-value customers? | C34: CTE, NTILE, SUM | D34: Use your SQL output | E34: Identifies the monthly revenue exposure of the highest-priority active segment | F34: Allocate retention resources based on both risk and customer value

Sheet Pivot_Analysis

Sheet Pivot_Contract
A3: Row Labels | B3: Count of Customer_ID | C3: Count of Churn
A4: 2-Year | B4: 1521 | C4: 1521 | D4: =C4/B4 -> 1
A5: Annual | B5: 3267 | C5: 3267 | D5: =C5/B5 -> 1
A6: Monthly | B6: 5212 | C6: 5212 | D6: =C6/B6 -> 1
A7: (blank)
A8: Grand Total | B8: 10000 | C8: 10000
A10: Churn | B10: Yes
A12: Row Labels | B12: Count of Customer_ID
A13: Basic | B13: 799
A14: Premium | B14: 466
A15: Standard | B15: 927
A16: Grand Total | B16: 2192
A19: Churn | B19: Yes
A21: Row Labels | B21: Count of Customer_ID
A22: 1 | B22: 63
A23: 2 | B23: 155
A24: 3 | B24: 273
A25: 4 | B25: 485
A26: 5 | B26: 1216
A27: Grand Total | B27: 2192

Sheet Data Quality Summary
A3: Check | B3: Before Cleaning | C3: Action | D3: After Cleaning
A4: Total Rows | B4: 10050 | C4: Remove duplicates | D4: 10000
A5: Duplicate Rows | B5: 50 | C5: Removed | D5: 0
A6: Missing Total Charges | B6: 70 | C6: Imputed | D6: 0
A7: Missing Payment Method | B7: 35 | C7: Set as Unknown | D7: 0
A8: Missing Satisfaction | B8: 25 | C8: Median Imputation | D8: 0
A9: Invalid Age | B9: 0 | C9: No action | D9: 0
A10: Invalid Churn | B10: 0 | C10: No action | D10: 0
